<?xml version="1.0" ?>
<!-- =================================================================================== -->
<!-- |    This document was autogenerated by xacro from main.xacro                     | -->
<!-- |    EDITING THIS FILE BY HAND IS NOT RECOMMENDED                                 | -->
<!-- =================================================================================== -->
<robot name="inspire_hand">
  <link name="left_hand_wrist_base_link">
    <inertial>
      <origin rpy="0 0 0" xyz="-2.4695E-06 0.0014729 0.032787"/>
      <mass value="0.065373"/>
      <inertia ixx="4.1551E-05" ixy="7.3802E-11" ixz="6.064E-09" iyy="4.1183E-05" iyz="8.3242E-09" izz="2.7991E-05"/>
    </inertial>
    <visual>
      <origin rpy="0 0 0" xyz="0 0 0"/>
      <geometry>
        <mesh filename="../meshes/visual/wrist_base_link.glb"/>
      </geometry>
    </visual>
    <collision>
      <origin rpy="0 0 0" xyz="0 0 0"/>
      <geometry>
        <mesh filename="../meshes/visual/wrist_base_link.glb"/>
      </geometry>
    </collision>
  </link>
  <link name="left_hand_wrist_link">
    <inertial>
      <origin rpy="0 0 0" xyz="-1.1356E-10 -7.0593E-06 7.9885E-05"/>
      <mass value="0.00056124"/>
      <inertia ixx="2.9483E-08" ixy="2.7024E-16" ixz="-1.1443E-17" iyy="2.9284E-08" iyz="-3.1652E-13" izz="2.2194E-09"/>
    </inertial>
    <visual>
      <origin rpy="0 0 0" xyz="0 0 0"/>
      <geometry>
        <mesh filename="../meshes/visual/L_wrist_link.glb"/>
      </geometry>
    </visual>
    <collision>
      <origin rpy="0 0 0" xyz="0 0 0"/>
      <geometry>
        <mesh filename="../meshes/visual/L_wrist_link.glb"/>
      </geometry>
    </collision>
  </link>
  <joint name="left_hand_wrist_pitch_joint" type="revolute">
    <origin rpy="1.5707963267948966 0 1.5707963267948966" xyz="0 0 0.0785"/>
    <parent link="left_hand_wrist_base_link"/>
    <child link="left_hand_wrist_link"/>
    <axis xyz="0 0 1"/>
    <limit effort="1" lower="-0.39549160850191506" upper="0.3860668305411457" velocity="0.5"/>
  </joint>
  <link name="left_hand_hand_base_link">
    <inertial>
      <origin rpy="0 0 0" xyz="-0.0011392 0.05204 0.0013473"/>
      <mass value="0.19286"/>
      <inertia ixx="9.3621E-05" ixy="-1.7903E-06" ixz="-6.7098E-07" iyy="9.5449E-05" iyz="-2.7765E-06" izz="0.00016048"/>
    </inertial>
    <visual>
      <origin rpy="0 0 0" xyz="0 0 0"/>
      <geometry>
        <mesh filename="../meshes/visual/L_hand_base_link.glb"/>
      </geometry>
    </visual>
    <collision>
      <origin rpy="0 0 0" xyz="0 0 0"/>
      <geometry>
        <mesh filename="../meshes/visual/L_hand_base_link.glb"/>
      </geometry>
    </collision>
  </link>
  <joint name="left_hand_wrist_yaw_joint" type="revolute">
    <origin rpy="0 -1.5707963267948966 0" xyz="0 0 0"/>
    <parent link="left_hand_wrist_link"/>
    <child link="left_hand_hand_base_link"/>
    <axis xyz="0 0 1"/>
    <limit effort="1" lower="-0.445058959258554" upper="0.445058959258554" velocity="0.5"/>
  </joint>
  <link name="left_hand_thumb_metacarpal_base">
    <inertial>
      <origin rpy="0 0 0" xyz="0.003828 0.00054788 -2.5428E-05"/>
      <mass value="0.0015177"/>
      <inertia ixx="3.6056E-08" ixy="5.7717E-09" ixz="-1.9602E-09" iyy="6.0741E-08" iyz="2.0752E-10" izz="5.6161E-08"/>
    </inertial>
    <visual>
      <origin rpy="0 0 0" xyz="0 0 0"/>
      <geometry>
        <mesh filename="../meshes/visual/L_thumb_metacarpal_base.glb"/>
      </geometry>
    </visual>
    <collision>
      <origin rpy="0 0 0" xyz="0 0 0"/>
      <geometry>
        <mesh filename="../meshes/visual/L_thumb_metacarpal_base.glb"/>
      </geometry>
    </collision>
  </link>
  <joint name="left_hand_thumb_CMC_yaw_joint" type="revolute">
    <origin rpy="1.5707963267948966 0.2617993877991494 0" xyz="0.02125 0.0285 -0.01515"/>
    <parent link="left_hand_hand_base_link"/>
    <child link="left_hand_thumb_metacarpal_base"/>
    <axis xyz="0 0 1"/>
    <limit effort="1" lower="-1.3089969389957472" upper="0" velocity="0.5"/>
  </joint>
  <link name="left_hand_thumb_metacarpal">
    <inertial>
      <origin rpy="0 0 0" xyz="0.025598 0.0011674 1.6981E-07"/>
      <mass value="0.026111"/>
      <inertia ixx="2.4138E-06" ixy="1.425E-07" ixz="-6.4106E-11" iyy="6.7215E-06" iyz="6.9289E-12" izz="7.9391E-06"/>
    </inertial>
    <visual>
      <origin rpy="0 0 0" xyz="0 0 0"/>
      <geometry>
        <mesh filename="../meshes/visual/thumb_metacarpal.glb"/>
      </geometry>
    </visual>
    <collision>
      <origin rpy="0 0 0" xyz="0 0 0"/>
      <geometry>
        <mesh filename="../meshes/visual/thumb_metacarpal.glb"/>
      </geometry>
    </collision>
  </link>
  <!--
      from sapien import Pose
      from transforms3d.euler import euler2quat, quat2euler
      import numpy as np
      pose_mb_m = Pose([0.0115, 0, 0.00075], euler2quat(np.pi/2, 0.62203, 0))
      new_pose_mb_m = pose_mb_m * Pose(q=euler2quat(0, 0, -0.2))
      quat2euler(new_pose_mb_m.q)
    -->
  <joint name="left_hand_thumb_CMC_pitch_joint" type="revolute">
    <origin rpy="1.5707963267948966 0.6831165238198015 0" xyz="0.0115 0 0.00075"/>
    <parent link="left_hand_thumb_metacarpal_base"/>
    <child link="left_hand_thumb_metacarpal"/>
    <axis xyz="0 0 1"/>
    <limit effort="1" lower="-0.4799655442984406" upper="0" velocity="0.5"/>
  </joint>
  <link name="left_hand_thumb_proximal">
    <inertial>
      <origin rpy="0 0 0" xyz="0.0096372 0.0056521 -1.5461E-07"/>
      <mass value="0.0076243"/>
      <inertia ixx="3.7133E-07" ixy="9.4972E-08" ixz="-1.1524E-11" iyy="7.9078E-07" iyz="9.5864E-13" izz="8.6326E-07"/>
    </inertial>
    <visual>
      <origin rpy="0 0 0" xyz="0 0 0"/>
      <geometry>
        <mesh filename="../meshes/visual/thumb_proximal.glb"/>
      </geometry>
    </visual>
    <collision>
      <origin rpy="0 0 0" xyz="0 0 0"/>
      <geometry>
        <mesh filename="../meshes/visual/thumb_proximal.glb"/>
      </geometry>
    </collision>
  </link>
  <joint name="left_hand_thumb_MCP_joint" type="revolute">
    <origin rpy="0 0 -0.003172" xyz="0.055852 -0.0040666 0"/>
    <parent link="left_hand_thumb_metacarpal"/>
    <child link="left_hand_thumb_proximal"/>
    <axis xyz="0 0 1"/>
    <limit effort="1" lower="-0.8" upper="0" velocity="0.5"/>
    <mimic joint="left_hand_thumb_CMC_pitch_joint" multiplier="1.3333333333333335" offset="-0.08144869842640205"/>
  </joint>
  <link name="left_hand_thumb_distal">
    <inertial>
      <origin rpy="0 0 0" xyz="0.01088 0.00050962 1.5765E-07"/>
      <mass value="0.0032026"/>
      <inertia ixx="8.142E-08" ixy="2.1827E-08" ixz="3.1474E-12" iyy="1.751E-07" iyz="-1.6913E-12" izz="1.8652E-07"/>
    </inertial>
    <visual>
      <origin rpy="0 0 0" xyz="0 0 0"/>
      <geometry>
        <mesh filename="../meshes/visual/thumb_distal.glb"/>
      </geometry>
    </visual>
    <collision>
      <origin rpy="0 0 0" xyz="0 0 0"/>
      <geometry>
        <mesh filename="../meshes/visual/thumb_distal.glb"/>
      </geometry>
    </collision>
  </link>
  <joint name="left_hand_thumb_IP_joint" type="revolute">
    <origin rpy="0 0 0.011853" xyz="0.022558 0.0020717 0"/>
    <parent link="left_hand_thumb_proximal"/>
    <child link="left_hand_thumb_distal"/>
    <axis xyz="0 0 1"/>
    <limit effort="1" lower="-0.4" upper="0" velocity="0.5"/>
    <!-- NOTE (stao): In order to ues physx fixed tendon to simulate 2 underactuated joints in series controlled by one joint, we need
    to have them mimic one after another. The original mimic tag is commented out and we rearrange the transformation to make it depend 
    on the parent joint instead of the grandparent joint. -->
    <!-- <mimic joint="left_hand_thumb_CMC_pitch_joint" multiplier="0.6666666666666667" offset="-0.040724349213201026"/> -->
    <mimic joint="left_hand_thumb_MCP_joint" multiplier="0.5" offset="0"/>
  </joint>
  <link name="left_hand_index_proximal">
    <inertial>
      <origin rpy="0 0 0" xyz="0.013292 -0.0019852 6.3987E-08"/>
      <mass value="0.0074557"/>
      <inertia ixx="3.0933E-07" ixy="1.1169E-07" ixz="6.8599E-12" iyy="8.2022E-07" iyz="4.1194E-13" izz="9.125E-07"/>
    </inertial>
    <visual>
      <origin rpy="0 0 0" xyz="0 0 0"/>
      <geometry>
        <mesh filename="../meshes/visual/index_ring_proximal.glb"/>
      </geometry>
    </visual>
    <collision>
      <origin rpy="0 0 0" xyz="0 0 0"/>
      <geometry>
        <mesh filename="../meshes/visual/index_ring_proximal.glb"/>
      </geometry>
    </collision>
  </link>
  <joint name="left_hand_index_MCP_joint" type="revolute">
    <origin rpy="1.5707963267948966 -0.12457000000000001 1.5359" xyz="0.027071 0.10464 0.0020953"/>
    <parent link="left_hand_hand_base_link"/>
    <child link="left_hand_index_proximal"/>
    <axis xyz="0 0 1"/>
    <limit effort="1" lower="-1.34" upper="0" velocity="0.5"/>
  </joint>
  <link name="left_hand_index_middle">
    <inertial>
      <origin rpy="0 0 0" xyz="0.018926 -0.0015379 -1.1076E-08"/>
      <mass value="0.0044472"/>
      <inertia ixx="1.4776E-07" ixy="2.0201E-07" ixz="-8.6133E-13" iyy="6.6739E-07" iyz="4.5149E-13" izz="7.4626E-07"/>
    </inertial>
    <visual>
      <origin rpy="0 0 0" xyz="0 0 0"/>
      <geometry>
        <mesh filename="../meshes/visual/index_ring_middle.glb"/>
      </geometry>
    </visual>
    <collision>
      <origin rpy="0 0 0" xyz="0 0 0"/>
      <geometry>
        <mesh filename="../meshes/visual/index_ring_middle.glb"/>
      </geometry>
    </collision>
  </link>
  <joint name="left_hand_index_PIP_joint" type="revolute">
    <origin rpy="0 0 0.0016248" xyz="0.030445 -0.010275 0"/>
    <parent link="left_hand_index_proximal"/>
    <child link="left_hand_index_middle"/>
    <axis xyz="0 0 1"/>
    <limit effort="1" lower="-1.5930946000000001" upper="0.04545" velocity="0.5"/>
    <mimic joint="left_hand_index_MCP_joint" multiplier="1.06399" offset="-0.16734800000000002"/>
  </joint>
  <link name="left_hand_middle_proximal">
    <inertial>
      <origin rpy="0 0 0" xyz="0.013292 -0.0019853 9.6516E-08"/>
      <mass value="0.0074556"/>
      <inertia ixx="3.0932E-07" ixy="1.1169E-07" ixz="7.0517E-12" iyy="8.2022E-07" iyz="-8.1193E-13" izz="9.1249E-07"/>
    </inertial>
    <visual>
      <origin rpy="0 0 0" xyz="0 0 0"/>
      <geometry>
        <mesh filename="../meshes/visual/middle_pinky_proximal.glb"/>
      </geometry>
    </visual>
    <collision>
      <origin rpy="0 0 0" xyz="0 0 0"/>
      <geometry>
        <mesh filename="../meshes/visual/middle_pinky_proximal.glb"/>
      </geometry>
    </collision>
  </link>
  <joint name="left_hand_middle_MCP_joint" type="revolute">
    <origin rpy="1.5707963267948966 -0.12457000000000001 1.5707963267948966" xyz="0.00775 0.105 0.0020953"/>
    <parent link="left_hand_hand_base_link"/>
    <child link="left_hand_middle_proximal"/>
    <axis xyz="0 0 1"/>
    <limit effort="1" lower="-1.34" upper="0" velocity="0.5"/>
  </joint>
  <link name="left_hand_middle_middle">
    <inertial>
      <origin rpy="0 0 0" xyz="0.020219 -0.0014516 1.2009E-08"/>
      <mass value="0.0048918"/>
      <inertia ixx="1.6257E-07" ixy="2.4465E-07" ixz="-1.7387E-12" iyy="8.8196E-07" iyz="-3.56E-13" izz="9.6871E-07"/>
    </inertial>
    <visual>
      <origin rpy="0 0 0" xyz="0 0 0"/>
      <geometry>
        <mesh filename="../meshes/visual/middle_middle.glb"/>
      </geometry>
    </visual>
    <collision>
      <origin rpy="0 0 0" xyz="0 0 0"/>
      <geometry>
        <mesh filename="../meshes/visual/middle_middle.glb"/>
      </geometry>
    </collision>
  </link>
  <joint name="left_hand_middle_PIP_joint" type="revolute">
    <origin rpy="0 0 -0.019795" xyz="0.030445 -0.010275 0"/>
    <parent link="left_hand_middle_proximal"/>
    <child link="left_hand_middle_middle"/>
    <axis xyz="0 0 1"/>
    <limit effort="1" lower="-1.5930946000000001" upper="0.04545" velocity="0.5"/>
    <mimic joint="left_hand_middle_MCP_joint" multiplier="1.06399" offset="-0.16734800000000002"/>
  </joint>
  <link name="left_hand_ring_proximal">
    <inertial>
      <origin rpy="0 0 0" xyz="0.013292 -0.0019853 9.267E-08"/>
      <mass value="0.0074556"/>
      <inertia ixx="3.0932E-07" ixy="1.1169E-07" ixz="6.3806E-12" iyy="8.2022E-07" iyz="-3.6905E-13" izz="9.1249E-07"/>
    </inertial>
    <visual>
      <origin rpy="0 0 0" xyz="0 0 0"/>
      <geometry>
        <mesh filename="../meshes/visual/index_ring_proximal.glb"/>
      </geometry>
    </visual>
    <collision>
      <origin rpy="0 0 0" xyz="0 0 0"/>
      <geometry>
        <mesh filename="../meshes/visual/index_ring_proximal.glb"/>
      </geometry>
    </collision>
  </link>
  <joint name="left_hand_ring_MCP_joint" type="revolute">
    <origin rpy="1.5707963267948966 -0.12457000000000001 1.6232" xyz="-0.011479 0.1045 0.0020953"/>
    <parent link="left_hand_hand_base_link"/>
    <child link="left_hand_ring_proximal"/>
    <axis xyz="0 0 1"/>
    <limit effort="1" lower="-1.34" upper="0" velocity="0.5"/>
  </joint>
  <link name="left_hand_ring_middle">
    <inertial>
      <origin rpy="0 0 0" xyz="0.018926 -0.0015379 -2.2563E-08"/>
      <mass value="0.0044472"/>
      <inertia ixx="1.4776E-07" ixy="2.0201E-07" ixz="2.6303E-13" iyy="6.6739E-07" iyz="-1.872E-13" izz="7.4626E-07"/>
    </inertial>
    <visual>
      <origin rpy="0 0 0" xyz="0 0 0"/>
      <geometry>
        <mesh filename="../meshes/visual/index_ring_middle.glb"/>
      </geometry>
    </visual>
    <collision>
      <origin rpy="0 0 0" xyz="0 0 0"/>
      <geometry>
        <mesh filename="../meshes/visual/index_ring_middle.glb"/>
      </geometry>
    </collision>
  </link>
  <joint name="left_hand_ring_PIP_joint" type="revolute">
    <origin rpy="0 0 0.0016262" xyz="0.030445 -0.010275 0"/>
    <parent link="left_hand_ring_proximal"/>
    <child link="left_hand_ring_middle"/>
    <axis xyz="0 0 1"/>
    <limit effort="1" lower="-1.5930946000000001" upper="0.04545" velocity="0.5"/>
    <mimic joint="left_hand_ring_MCP_joint" multiplier="1.06399" offset="-0.16734800000000002"/>
  </joint>
  <link name="left_hand_pinky_proximal">
    <inertial>
      <origin rpy="0 0 0" xyz="0.013292 -0.0019853 9.9172E-08"/>
      <mass value="0.0074556"/>
      <inertia ixx="3.0932E-07" ixy="1.1169E-07" ixz="6.5494E-12" iyy="8.2022E-07" iyz="-6.477E-13" izz="9.1249E-07"/>
    </inertial>
    <visual>
      <origin rpy="0 0 0" xyz="0 0 0"/>
      <geometry>
        <mesh filename="../meshes/visual/middle_pinky_proximal.glb"/>
      </geometry>
    </visual>
    <collision>
      <origin rpy="0 0 0" xyz="0 0 0"/>
      <geometry>
        <mesh filename="../meshes/visual/middle_pinky_proximal.glb"/>
      </geometry>
    </collision>
  </link>
  <joint name="left_hand_pinky_MCP_joint" type="revolute">
    <origin rpy="1.5707963267948966 -0.12457000000000001 1.6755" xyz="-0.030655 0.10299 0.0020953"/>
    <parent link="left_hand_hand_base_link"/>
    <child link="left_hand_pinky_proximal"/>
    <axis xyz="0 0 1"/>
    <limit effort="1" lower="-1.34" upper="0" velocity="0.5"/>
  </joint>
  <link name="left_hand_pinky_middle">
    <inertial>
      <origin rpy="0 0 0" xyz="0.015705 -0.0017319 3.0193E-05"/>
      <mass value="0.00358"/>
      <inertia ixx="1.1688E-07" ixy="1.3011E-07" ixz="-5.7708E-10" iyy="3.6706E-07" iyz="3.7863E-10" izz="4.2837E-07"/>
    </inertial>
    <visual>
      <origin rpy="0 0 0" xyz="0 0 0"/>
      <geometry>
        <mesh filename="../meshes/visual/pinky_middle.glb"/>
      </geometry>
    </visual>
    <collision>
      <origin rpy="0 0 0" xyz="0 0 0"/>
      <geometry>
        <mesh filename="../meshes/visual/pinky_middle.glb"/>
      </geometry>
    </collision>
  </link>
  <joint name="left_hand_pinky_PIP_joint" type="revolute">
    <origin rpy="0 0 0.090322" xyz="0.030445 -0.010275 0"/>
    <parent link="left_hand_pinky_proximal"/>
    <child link="left_hand_pinky_middle"/>
    <axis xyz="0 0 1"/>
    <limit effort="1" lower="-1.5930946000000001" upper="0.04545" velocity="0.5"/>
    <mimic joint="left_hand_pinky_MCP_joint" multiplier="1.06399" offset="-0.16734800000000002"/>
  </joint>
  <link name="left_hand_thumb_tip"/>
  <joint name="left_hand_thumb_tip_joint" type="fixed">
    <origin rpy="0 0 0" xyz="0.024859 -0.000031 0"/>
    <parent link="left_hand_thumb_distal"/>
    <child link="left_hand_thumb_tip"/>
  </joint>
  <link name="left_hand_index_tip"/>
  <joint name="left_hand_index_tip_joint" type="fixed">
    <origin rpy="0 0 0" xyz="0.043944 -0.009147 0"/>
    <parent link="left_hand_index_middle"/>
    <child link="left_hand_index_tip"/>
  </joint>
  <link name="left_hand_middle_tip"/>
  <joint name="left_hand_middle_tip_joint" type="fixed">
    <origin rpy="0 0 0" xyz="0.047746 -0.009066 0"/>
    <parent link="left_hand_middle_middle"/>
    <child link="left_hand_middle_tip"/>
  </joint>
  <link name="left_hand_ring_tip"/>
  <joint name="left_hand_ring_tip_joint" type="fixed">
    <origin rpy="0 0 0" xyz="0.043944 -0.009147 0"/>
    <parent link="left_hand_ring_middle"/>
    <child link="left_hand_ring_tip"/>
  </joint>
  <link name="left_hand_pinky_tip"/>
  <joint name="left_hand_pinky_tip_joint" type="fixed">
    <origin rpy="0 0 0" xyz="0.035855 -0.009619 0"/>
    <parent link="left_hand_pinky_middle"/>
    <child link="left_hand_pinky_tip"/>
  </joint>
</robot>
