<?xml version="1.0" encoding="UTF-8"?>
<robot name="cartpole2">
  <joint name="hinge_1" type="continuous">
    <origin xyz="0. 0. 0." rpy="0. 0. 1.5707964"/>
    <parent link="cartpole_cart_cart"/>
    <child link="cartpole_cart_pole_1"/>
    <axis xyz="1. 0. 0."/>
  </joint>
  <joint name="slider" type="prismatic">
    <origin xyz="0. 0. 1." rpy="0. 0. 0."/>
    <parent link="Root"/>
    <child link="cartpole_cart_cart"/>
    <axis xyz="1. 0. 0."/>
    <limit lower="-1.8" upper="1.8" effort="0." velocity="1000000."/>
  </joint>
  <link name="Root">
    <visual>
      <origin xyz="0. 0. -0.05" rpy="0. 0. 0."/>
      <geometry>
        <mesh filename="meshes/worldBody_floor_visuals_floor.obj" scale="1. 1. 1."/>
      </geometry>
    </visual>
  </link>
  <link name="cartpole_cart_cart">
    <visual>
      <origin xyz="0. 0. 0." rpy="0. 0. 0."/>
      <geometry>
        <box size="0.4 0.3 0.2"/>
      </geometry>
    </visual>
    <collision>
      <origin xyz="0. 0. 0." rpy="0. 0. 0."/>
      <geometry>
        <box size="0.4 0.3 0.2"/>
      </geometry>
    </collision>
  </link>
  <link name="cartpole_cart_pole_1">
    <visual>
      <origin xyz="0. 0. 0.5" rpy="0. 0. -1.5707964"/>
      <geometry>
        <cylinder radius="0.045" length="1."/>
      </geometry>
    </visual>
    <collision>
      <origin xyz="0. 0. 0.5" rpy="0. 0. -1.5707964"/>
      <geometry>
        <cylinder radius="0.045" length="1."/>
      </geometry>
    </collision>
  </link>
</robot>
