<mujoco model="two-link planar reacher">
  <include file="./common/skybox.xml"/>
  <include file="./common/visual.xml"/>
  <include file="./common/materials.xml"/>
  <asset>
    <texture name="grid" type="2d" builtin="checker" rgb1=".1 .2 .3" rgb2=".2 .3 .4" width="300" height="300" mark="edge" markrgb=".2 .3 .4"/>
    <material name="grid" texture="grid" texrepeat="1 1" texuniform="true" reflectance=".2"/>
    <material name="self" rgba=".7 .5 .3 1"/>
    <material name="self_default" rgba=".7 .5 .3 1"/>
    <material name="self_highlight" rgba="0 .5 .3 1"/>
    <material name="effector" rgba=".7 .4 .2 1"/>
    <material name="effector_default" rgba=".7 .4 .2 1"/>
    <material name="effector_highlight" rgba="0 .5 .3 1"/>
    <material name="decoration" rgba=".3 .5 .7 1"/>
    <material name="eye" rgba="0 .2 1 1"/>
    <material name="target" rgba=".6 .3 .3 1"/>
    <material name="target_default" rgba=".6 .3 .3 1"/>
    <material name="target_highlight" rgba=".6 .3 .3 .4"/>
    <material name="site" rgba=".5 .5 .5 .3"/>
  </asset>
  <option timestep="0.02">
    <flag contact="disable"/>
  </option>

  <default>
    <joint type="hinge" axis="0 0 1" damping="0.01"/>
    <motor gear=".05" ctrlrange="-1 1" ctrllimited="true"/>
  </default>

  <worldbody>
    <light name="light" pos="0 0 1"/>
    <camera name="fixed" pos="0 0 .75" quat="1 0 0 0"/>
    <!-- Arena -->
    <geom name="ground" type="plane" pos="0 0 0" size=".3 .3 10" material="grid"/>
    <geom name="wall_x" type="plane" pos="-.3 0 .02" zaxis="1 0 0"  size=".02 .3 .02" material="decoration"/>
    <geom name="wall_y" type="plane" pos="0 -.3 .02" zaxis="0 1 0"  size=".3 .02 .02" material="decoration"/>
    <geom name="wall_neg_x" type="plane" pos=".3 0 .02" zaxis="-1 0 0"  size=".02 .3 .02" material="decoration"/>
    <geom name="wall_neg_y" type="plane" pos="0 .3 .02" zaxis="0 -1 0"  size=".3 .02 .02" material="decoration"/>

    <!-- Arm -->
    <geom name="root" type="cylinder" fromto="0 0 0 0 0 0.02" size=".011" material="decoration"/>
    <body name="arm" pos="0 0 .01">
      <geom name="arm" type="capsule" fromto="0 0 0 0.12 0 0" size=".01" material="self"/>
      <joint name="shoulder"/>
      <body name="hand" pos=".12 0 0">
        <geom name="hand" type="capsule" fromto="0 0 0 0.1 0 0" size=".01" material="self"/>
        <joint name="wrist" limited="true" range="-160 160"/>
        <body name="finger" pos=".12 0 0">
          <camera name="hand" pos="0 0 .2" mode="track"/>
          <geom name="finger" type="sphere" size=".01" material="effector"/>
        </body>
      </body>
    </body>
    <!-- Target -->
    <geom name="target" pos="0 0 .01" material="target" type="sphere" size=".05"/>
  </worldbody>

  <actuator>
    <motor name="shoulder" joint="shoulder"/>
    <motor name="wrist" joint="wrist"/>
  </actuator>
</mujoco>