<?xml version="1.0" encoding="utf-8"?>
<robot name="xarm7">
  <material name="Black">
    <color rgba="0.0 0.0 0.0 1.0"/>
  </material>
  <material name="Red">
    <color rgba="0.8 0.0 0.0 1.0"/>
  </material>
  <material name="White">
    <color rgba="1.0 1.0 1.0 1.0"/>
  </material>
  <material name="Silver">
    <color rgba="0.753 0.753 0.753 1.0"/>
  </material>
  <!-- <link name="world"/>
  <joint name="world_joint" type="fixed">
    <parent link="world"/>
    <child link="link_base"/>
    <origin rpy="0 0 0" xyz="0 0 0"/>
  </joint> -->
  <link name="link_base">
    <inertial>
      <origin rpy="0 0 0" xyz="-0.021131 -0.0016302 0.056488"/>
      <mass value="0.88556"/>
      <inertia ixx="0.0030595" ixy="0.00012259" ixz="-0.00062705" iyy="0.0037783" iyz="0.00027023" izz="0.0020125"/>
    </inertial>
    <visual>
      <geometry>
        <mesh filename="meshes/xarm7_new/link_base_textured.glb"/>
      </geometry>
      <origin rpy="0 0 0" xyz="0 0 0"/>
      <!-- <material name="White"/> -->
    </visual>
    <collision>
      <geometry>
        <mesh filename="meshes/xarm7_new/link_base_textured.glb"/>
      </geometry>
      <origin rpy="0 0 0" xyz="0 0 0"/>
    </collision>
  </link>
  <link name="link1">
    <inertial>
      <origin rpy="0 0 0" xyz="-0.0002 0.02905 -0.01233"/>
      <mass value="2.382"/>
      <inertia ixx="0.0056905" ixy="-1.579e-05" ixz="5.125e-06" iyy="0.0049566" iyz="-0.000873378" izz="0.003316654"/>
    </inertial>
    <visual>
      <geometry>
        <mesh filename="meshes/xarm7_new/link1_textured.glb"/>
      </geometry>
      <origin rpy="0 0 0" xyz="0 0 0"/>
      <!-- <material name="White"/> -->
    </visual>
    <collision>
      <geometry>
        <mesh filename="meshes/xarm7_new/link1_textured.glb"/>
      </geometry>
      <origin rpy="0 0 0" xyz="0 0 0"/>
    </collision>
  </link>
  <joint name="joint1" type="revolute">
    <origin rpy="0 0 0" xyz="0 0 0.267"/>
    <parent link="link_base"/>
    <child link="link1"/>
    <axis xyz="0 0 1"/>
    <limit effort="50" lower="-6.283185307179586" upper="6.283185307179586" velocity="3.14"/>
    <dynamics damping="10" friction="1"/>
  </joint>
  <link name="link2">
    <inertial>
      <origin rpy="0 0 0" xyz="0.00022 -0.12856 0.01735"/>
      <mass value="1.869"/>
      <inertia ixx="0.0095989" ixy="1.541e-06" ixz="5.56e-06" iyy="0.00382472" iyz="-0.00317156" izz="0.007565669"/>
    </inertial>
    <visual>
      <geometry>
        <mesh filename="meshes/xarm7_new/link2_textured.glb"/>
      </geometry>
      <origin rpy="0 0 0" xyz="0 0 0"/>
      <!-- <material name="White"/> -->
    </visual>
    <collision>
      <geometry>
        <mesh filename="meshes/xarm7_new/link2_textured.glb"/>
      </geometry>
      <origin rpy="0 0 0" xyz="0 0 0"/>
    </collision>
  </link>
  <joint name="joint2" type="revolute">
    <origin rpy="-1.5708 -1.5708 0" xyz="0 0 0"/>
    <parent link="link1"/>
    <child link="link2"/>
    <axis xyz="0 0 1"/>
    <limit effort="50" lower="-2.059" upper="2.0944" velocity="3.14"/>
    <dynamics damping="10" friction="1"/>
  </joint>
  <link name="link3">
    <inertial>
      <origin rpy="0 0 0" xyz="0.0466 -0.02463 -0.00768"/>
      <mass value="1.6383"/>
      <inertia ixx="0.00310955" ixy="0.00030837" ixz="-0.00058453" iyy="0.00264483" iyz="0.000338893" izz="0.0026624"/>
    </inertial>
    <visual>
      <geometry>
        <mesh filename="meshes/xarm7_new/link3_textured.glb"/>
      </geometry>
      <origin rpy="0 0 0" xyz="0 0 0"/>
      <!-- <material name="White"/> -->
    </visual>
    <collision>
      <geometry>
        <mesh filename="meshes/xarm7_new/link3_textured.glb"/>
      </geometry>
      <origin rpy="0 0 0" xyz="0 0 0"/>
    </collision>
  </link>
  <joint name="joint3" type="revolute">
    <origin rpy="1.5708 0 0" xyz="0 -0.293 0"/>
    <parent link="link2"/>
    <child link="link3"/>
    <axis xyz="0 0 1"/>
    <limit effort="30" lower="-6.283185307179586" upper="6.283185307179586" velocity="3.14"/>
    <dynamics damping="5" friction="1"/>
  </joint>
  <link name="link4">
    <inertial>
      <origin rpy="0 0 0" xyz="0.07047 -0.11575 0.012"/>
      <mass value="1.7269"/>
      <inertia ixx="0.005889" ixy="0.00137112" ixz="0.00088143" iyy="0.00359703" iyz="-0.001762155" izz="0.00543244"/>
    </inertial>
    <visual>
      <geometry>
        <mesh filename="meshes/xarm7_new/link4_textured.glb"/>
      </geometry>
      <origin rpy="0 0 0" xyz="0 0 0"/>
      <!-- <material name="White"/> -->
    </visual>
    <collision>
      <geometry>
        <mesh filename="meshes/xarm7_new/link4_textured.glb"/>
      </geometry>
      <origin rpy="0 0 0" xyz="0 0 0"/>
    </collision>
  </link>
  <joint name="joint4" type="revolute">
    <origin rpy="1.5708 0 0" xyz="0.0525 0 0"/>
    <parent link="link3"/>
    <child link="link4"/>
    <axis xyz="0 0 1"/>
    <limit effort="30" lower="-0.19198" upper="3.927" velocity="3.14"/>
    <dynamics damping="5" friction="1"/>
  </joint>
  <link name="link5">
    <inertial>
      <origin rpy="0 0 0" xyz="-0.00032 0.01604 -0.026"/>
      <mass value="1.3203"/>
      <inertia ixx="0.00534665" ixy="1.5117e-05" ixz="-3.69e-07" iyy="0.0049779" iyz="-0.00022132" izz="0.0013624"/>
    </inertial>
    <visual>
      <geometry>
        <mesh filename="meshes/xarm7_new/link5_textured.glb"/>
      </geometry>
      <origin rpy="0 0 0" xyz="0 0 0"/>
      <!-- <material name="White"/> -->
    </visual>
    <collision>
      <geometry>
        <mesh filename="meshes/xarm7_new/link5_textured.glb"/>
      </geometry>
      <origin rpy="0 0 0" xyz="0 0 0"/>
    </collision>
  </link>
  <joint name="joint5" type="revolute">
    <origin rpy="1.5708 0 0" xyz="0.0775 -0.3425 0"/>
    <parent link="link4"/>
    <child link="link5"/>
    <axis xyz="0 0 1"/>
    <limit effort="30" lower="-6.283185307179586" upper="6.283185307179586" velocity="3.14"/>
    <dynamics damping="5" friction="1"/>
  </joint>
  <link name="link6">
    <inertial>
      <origin rpy="0 0 0" xyz="0.06469 0.03278 0.02141"/>
      <mass value="1.325"/>
      <inertia ixx="0.0014745" ixy="-0.000488" ixz="0.0002953" iyy="0.0019037" iyz="0.00014749" izz="0.0023652"/>
    </inertial>
    <visual>
      <geometry>
        <mesh filename="meshes/xarm7_new/link6_textured.glb"/>
      </geometry>
      <origin rpy="0 0 0" xyz="0 0 0"/>
      <!-- <material name="White"/> -->
    </visual>
    <collision>
      <geometry>
        <mesh filename="meshes/xarm7_new/link6_textured.glb"/>
      </geometry>
      <origin rpy="0 0 0" xyz="0 0 0"/>
    </collision>
  </link>
  <joint name="joint6" type="revolute">
    <origin rpy="1.5708 0 0" xyz="0 0 0"/>
    <parent link="link5"/>
    <child link="link6"/>
    <axis xyz="0 0 1"/>
    <limit effort="20" lower="-1.69297" upper="3.141592653589793" velocity="3.14"/>
    <dynamics damping="2" friction="1"/>
  </joint>
  <link name="link7">
    <inertial>
      <origin rpy="0 0 0" xyz="0 -0.00677 -0.01098"/>
      <mass value="0.17"/>
      <inertia ixx="9.3e-05" ixy="-0.0" ixz="-0.0" iyy="5.87e-05" iyz="-3.6e-06" izz="0.000132"/>
    </inertial>
    <visual>
      <geometry>
        <mesh filename="meshes/xarm7_new/link7_silver.glb"/>
      </geometry>
      <origin rpy="0 0 0" xyz="0 0 0"/>
      <!-- <material name="Silver"/> -->
    </visual>
    <collision>
      <geometry>
        <mesh filename="meshes/end_tool/end_tool.STL"/>
      </geometry>
      <origin rpy="0 0 0" xyz="0 0 0"/>
    </collision>
  </link>
  <joint name="joint7" type="revolute">
    <origin rpy="-1.5708 0 0" xyz="0.076 0.097 0"/>
    <parent link="link6"/>
    <child link="link7"/>
    <axis xyz="0 0 1"/>
    <limit effort="20" lower="-6.283185307179586" upper="6.283185307179586" velocity="3.14"/>
    <dynamics damping="2" friction="1"/>
  </joint>

  <joint name="joint_eef" type="fixed">
    <origin xyz="0.005 -0.02 0.05" rpy="0 0 -1.57079"/>
    <parent link="link7"/>
    <child link="right_base_link"/>
  </joint>

  <!-- <link name="base">
    <visual name="wrist_mesh">
      <origin rpy="0 0 0" xyz="0 0 0"/>
      <geometry>
        <mesh filename="../ability_hand/meshes/visual/wristmesh.glb"/>
      </geometry>
    </visual>
    <collision>
      <origin xyz="0 0 0" rpy="0 0 0"/>
      <geometry>
        <mesh filename="../ability_hand/meshes/collision/wristmesh_C.obj"/>
      </geometry>
    </collision>
    <inertial>
      <mass value="0.200"/>
      <inertia ixx="978.26e-6" ixy="87.34e-6" ixz="322.99e-6" iyy="1244.78e-6" iyz="244.74e-6" izz="456.22e-6"/>
      <origin xyz="22.41911e-3 -0.15798201e-3 -0.01319866e-3" rpy="0 0 0"/>
    </inertial>
  </link>

  <joint name="wrist2thumb" type="fixed">
    <parent link="base"/>
    <child link="right_base_link"/>
    <origin xyz="-24.0476665e-3 -5.78124745e-3 32.32964923e-3" rpy="0 -1.57074213 3.14148426"/>
  </joint> -->

  <link name="right_base_link">
    <inertial>
      <origin xyz="-0.0211971496867713 -0.00980607468332059 0.0291539210995797" rpy="0 0 0"/>
      <mass value="0.226288892912552"/>
      <inertia ixx="0.25807950453196" ixy="-0.00483159310640912" ixz="-0.00079714751769554" iyy="0.35869194959045403" iyz="-0.00373467589382574" izz="0.161017137787831" />
    </inertial>
    <visual>
      <origin xyz="0 0 0" rpy="0 0 0"/>
      <geometry>
        <mesh filename="meshes/inspire_hand/right_palm.glb"/>
      </geometry>
    </visual>
    <collision>
      <origin xyz="0 0 0" rpy="0 0 0"/>
      <geometry>
        <mesh filename="meshes/inspire_hand/right_palm.glb"/>
      </geometry>
    </collision>
  </link>
  <link name="right_link1">
    <inertial>
      <origin xyz="0.0107728972114067 0.00213787716764519 -1.04416311069722E-07" rpy="0 0 0"/>
      <mass value="0.00330630285835291"/>
      <inertia ixx="0.000155839473420917" ixy="-3.78961194376192e-05" ixz="-3.77173039190185e-09" iyy="0.000530393024372046" iyz="-7.4062368302925e-10" izz="0.0005551700373396271" />
    </inertial>
    <visual>
      <origin xyz="0 0 0" rpy="0 0 0"/>
      <geometry>
        <mesh filename="meshes/inspire_hand/finger.glb"/>
      </geometry>
    </visual>
    <collision>
      <origin xyz="0 0 0" rpy="0 0 0"/>
      <geometry>
        <mesh filename="meshes/inspire_hand/finger.glb"/>
      </geometry>
    </collision>
  </link>
  <joint name="right_joint1" type="revolute">
    <origin xyz="0.0068852 -0.0077547 0.08206" rpy="1.4604 -1.2485 -1.466"/>
    <parent link="right_base_link"/>
    <child link="right_link1"/>
    <axis xyz="0 0 1"/>
    <limit lower="-1.461" upper="0.253" effort="1" velocity="1"/>
  </joint>
  <link name="right_link11">
    <inertial>
      <origin xyz="0.0190179143887291 0.00563447080965412 1.42999243835096E-08" rpy="0 0 0"/>
      <mass value="0.00453366979354947"/>
      <inertia ixx="8.56969401817861e-05" ixy="-3.6550236316683e-05" ixz="1.43626963228685e-09" iyy="0.0007582333342196199" iyz="7.37235171817566e-10" izz="0.000768832168975162" />
    </inertial>
    <visual>
      <origin xyz="0 0 0" rpy="0 0 0"/>
      <geometry>
        <mesh filename="meshes/inspire_hand/tip0.glb"/>
      </geometry>
    </visual>
    <collision>
      <origin xyz="0 0 0" rpy="0 0 0"/>
      <geometry>
        <mesh filename="meshes/inspire_hand/tip0.glb"/>
      </geometry>
    </collision>
  </link>
  <joint name="right_joint11" type="revolute">
    <origin xyz="0.032132 0 0" rpy="-5.2101E-10 -2.8366E-11 -0.05439"/>
    <parent link="right_link1"/>
    <child link="right_link11"/>
    <axis xyz="0 0 1"/>
    <limit lower="-1.66" upper="-0.068" effort="1" velocity="1"/>
  </joint>
  <link name="right_link2">
    <inertial>
      <origin xyz="0.0107729848426235 0.00213783905889497 -1.15186638033338E-07" rpy="0 0 0"/>
      <mass value="0.00330621735666597"/>
      <inertia ixx="0.000155837836898236" ixy="-3.78957279466946e-05" ixz="-4.46779108562076e-09" iyy="0.000530385092299547" iyz="-1.06162548544094e-09" izz="0.00055516472017082" />
    </inertial>
    <visual>
      <origin xyz="0 0 0" rpy="0 0 0"/>
      <geometry>
        <mesh filename="meshes/inspire_hand/finger.glb"/>
      </geometry>
    </visual>
    <collision>
      <origin xyz="0 0 0" rpy="0 0 0"/>
      <geometry>
        <mesh filename="meshes/inspire_hand/finger.glb"/>
      </geometry>
    </collision>
  </link>
  <joint name="right_joint2" type="revolute">
    <origin xyz="-0.012436 -0.0077547 0.082423" rpy="1.5708 -1.4093 -1.5708"/>
    <parent link="right_base_link"/>
    <child link="right_link2"/>
    <axis xyz="0 0 1"/>
    <limit lower="-1.57" upper="0.109" effort="1" velocity="1"/>
  </joint>
  <link name="right_link22">
    <inertial>
      <origin xyz="0.0190179449257988 0.00563447974623821 1.95695375043714E-08" rpy="0 0 0"/>
      <mass value="0.00453367027223764"/>
      <inertia ixx="8.569696578516839e-05" ixy="-3.655092334419e-05" ixz="1.59947670219807e-09" iyy="0.000758233058731142" iyz="6.82745605693632e-10" izz="0.000768832058388577" />
    </inertial>
    <visual>
      <origin xyz="0 0 0" rpy="0 0 0"/>
      <geometry>
        <mesh filename="meshes/inspire_hand/tip0.glb"/>
      </geometry>
    </visual>
    <collision>
      <origin xyz="0 0 0" rpy="0 0 0"/>
      <geometry>
        <mesh filename="meshes/inspire_hand/tip0.glb"/>
      </geometry>
    </collision>
  </link>
  <joint name="right_joint22" type="revolute">
    <origin xyz="0.032132 0 0" rpy="-5.0853E-10 -1.1686E-10 -0.22588"/>
    <parent link="right_link2"/>
    <child link="right_link22"/>
    <axis xyz="0 0 1"/>
    <limit lower="-1.545" upper="0.048" effort="1" velocity="1"/>
  </joint>
  <link name="right_link3">
    <inertial>
      <origin xyz="0.0107730870011274 0.00213783984115729 -1.4434440405442E-07" rpy="0 0 0"/>
      <mass value="0.00330616517571661"/>
      <inertia ixx="0.000155836709865158" ixy="-3.78959914486162e-05" ixz="-4.8756362673358205e-09" iyy="0.0005303808571582551" iyz="-1.32040927550488e-09" izz="0.000555162479884557" />
    </inertial>
    <visual>
      <origin xyz="0 0 0" rpy="0 0 0"/>
      <geometry>
        <mesh filename="meshes/inspire_hand/finger.glb"/>
      </geometry>
    </visual>
    <collision>
      <origin xyz="0 0 0" rpy="0 0 0"/>
      <geometry>
        <mesh filename="meshes/inspire_hand/finger.glb"/>
      </geometry>
    </collision>
  </link>
  <joint name="right_joint3" type="revolute">
    <origin xyz="-0.031665 -0.0077547 0.08192" rpy="1.9857 -1.4406 -1.9826"/>
    <parent link="right_base_link"/>
    <child link="right_link3"/>
    <axis xyz="0 0 1"/>
    <limit lower="-1.66" upper="-0.02" effort="1" velocity="1"/>
  </joint>
  <link name="right_link33">
    <inertial>
      <origin xyz="0.0190179173374263 0.00563447812355383 2.17778843153438E-08" rpy="0 0 0"/>
      <mass value="0.00453366946672897"/>
      <inertia ixx="8.56969954123567e-05" ixy="-3.65502686172672e-05" ixz="1.914131820864e-09" iyy="0.0007582323909435819" iyz="6.102905747127e-10" izz="0.000768831206632801" />
    </inertial>
    <visual>
      <origin xyz="0 0 0" rpy="0 0 0"/>
      <geometry>
        <mesh filename="meshes/inspire_hand/tip0.glb"/>
      </geometry>
    </visual>
    <collision>
      <origin xyz="0 0 0" rpy="0 0 0"/>
      <geometry>
        <mesh filename="meshes/inspire_hand/tip0.glb"/>
      </geometry>
    </collision>
  </link>
  <joint name="right_joint33" type="revolute">
    <origin xyz="0.032132 0 0" rpy="-5.0314E-10 -1.3824E-10 -0.26815"/>
    <parent link="right_link3"/>
    <child link="right_link33"/>
    <axis xyz="0 0 1"/>
    <limit lower="-1.449" upper="0.259" effort="1" velocity="1"/>
  </joint>
  <link name="right_link4">
    <inertial>
      <origin xyz="0.0107728838996999 0.00213787812202321 -1.47685512180695E-07" rpy="0 0 0"/>
      <mass value="0.00330630460851054"/>
      <inertia ixx="0.00015583983488180798" ixy="-3.7896641348538795e-05" ixz="-5.46215465743034e-09" iyy="0.0005303937756232501" iyz="-1.57695349654339e-09" izz="0.000555171477054147" />
    </inertial>
    <visual>
      <origin xyz="0 0 0" rpy="0 0 0"/>
      <geometry>
        <mesh filename="meshes/inspire_hand/finger.glb"/>
      </geometry>
    </visual>
    <collision>
      <origin xyz="0 0 0" rpy="0 0 0"/>
      <geometry>
        <mesh filename="meshes/inspire_hand/finger.glb"/>
      </geometry>
    </collision>
  </link>
  <joint name="right_joint4" type="revolute">
    <origin xyz="-0.050841 -0.0077547 0.08041" rpy="2.0186 -1.327 -2.007"/>
    <parent link="right_base_link"/>
    <child link="right_link4"/>
    <axis xyz="0 0 1"/>
    <limit lower="-1.564" upper="0.13" effort="1" velocity="1"/>
  </joint>
  <link name="right_link44">
    <inertial>
      <origin xyz="0.0155924434001128 0.00555617869155978 -1.05483765444614E-07" rpy="0 0 0"/>
      <mass value="0.00356888715893842"/>
      <inertia ixx="6.67772840408144e-05" ixy="-2.70391833548355e-05" ixz="-3.26434716125092e-09" iyy="0.00043341942510117897" iyz="-9.18888508148905e-10" izz="0.000439763878420807" />
    </inertial>
    <visual>
      <origin xyz="0 0 0" rpy="0 0 0"/>
      <geometry>
        <mesh filename="meshes/inspire_hand/tip1.glb"/>
      </geometry>
    </visual>
    <collision>
      <origin xyz="0 0 0" rpy="0 0 0"/>
      <geometry>
        <mesh filename="meshes/inspire_hand/tip1.glb"/>
      </geometry>
    </collision>
  </link>
  <joint name="right_joint44" type="revolute">
    <origin xyz="0.032132 0 0" rpy="-5.1334E-10 -9.3483E-11 -0.18013"/>
    <parent link="right_link4"/>
    <child link="right_link44"/>
    <axis xyz="0 0 1"/>
    <limit lower="-1.573" upper="0.134" effort="1" velocity="1"/>
  </joint>
  <link name="right_link5">
    <inertial>
      <origin xyz="-0.00433166459951286 0.000656790554769388 0.000486675184306562" rpy="0 0 0"/>
      <mass value="0.00487393910083768"/>
      <inertia ixx="0.000130409345970056" ixy="8.919981607298109e-06" ixz="-1.76607007575074e-05" iyy="0.00017058032498292" iyz="1.0277140403717899e-06" izz="0.000211710622768954" />
    </inertial>
    <visual>
      <origin xyz="0 0 0" rpy="0 0 0"/>
      <geometry>
        <mesh filename="meshes/inspire_hand/right_thumb_root.glb"/>
      </geometry>
    </visual>
    <collision>
      <origin xyz="0 0 0" rpy="0 0 0"/>
      <geometry>
        <mesh filename="meshes/inspire_hand/right_thumb_root.glb"/>
      </geometry>
    </collision>
  </link>
  <joint name="right_joint5" type="revolute">
    <origin xyz="0.0010638 -0.025 0.0059231" rpy="1.5708 2.455E-15 2.3555"/>
    <parent link="right_base_link"/>
    <child link="right_link5"/>
    <axis xyz="0 -1 0"/>
    <limit lower="-0.329" upper="0.803" effort="1" velocity="1"/>
  </joint>
  <link name="right_link51">
    <inertial>
      <origin xyz="0.0261736471642429 0.00353664240332538 -7.35522423800372E-08" rpy="0 0 0"/>
      <mass value="0.00652741708580189"/>
      <inertia ixx="0.0008936634782870071" ixy="6.28882108303181e-05" ixz="-3.67789097092471e-08" iyy="0.00237350868720489" iyz="8.30149702319962e-09" izz="0.0027502170955407998" />
    </inertial>
    <visual>
      <origin xyz="0 0 0" rpy="0 0 0"/>
      <geometry>
        <mesh filename="meshes/inspire_hand/thumb_base.glb"/>
      </geometry>
    </visual>
    <collision>
      <origin xyz="0 0 0" rpy="0 0 0"/>
      <geometry>
        <mesh filename="meshes/inspire_hand/thumb_base.glb"/>
      </geometry>
    </collision>
  </link>
  <joint name="right_joint51" type="revolute">
    <origin xyz="-0.0115 -0.00075 0" rpy="-1.4988E-15 -5.5511E-17 1.8988"/>
    <parent link="right_link5"/>
    <child link="right_link51"/>
    <axis xyz="0 0 1"/>
    <limit lower="-0.221" upper="0.218" effort="1" velocity="1"/>
  </joint>
  <link name="right_link52">
    <inertial>
      <origin xyz="-0.00731595394729753 -0.00552216810488045 1.31327036717588E-07" rpy="0 0 0"/>
      <mass value="0.00226947954597765"/>
      <inertia ixx="0.000172809908882086" ixy="4.52296648937248e-05" ixz="-3.78399670014347e-09" iyy="0.000278044490402836" iyz="1.5225345233066e-10" izz="0.000299628844053565" />
    </inertial>
    <visual>
      <origin xyz="0 0 0" rpy="0 0 0"/>
      <geometry>
        <mesh filename="meshes/inspire_hand/thumb_middle.glb"/>
      </geometry>
    </visual>
    <collision>
      <origin xyz="0 0 0" rpy="0 0 0"/>
      <geometry>
        <mesh filename="meshes/inspire_hand/thumb_middle.glb"/>
      </geometry>
    </collision>
  </link>
  <joint name="right_joint52" type="revolute">
    <origin xyz="0.056001 0 0" rpy="-1.3323E-15 -2.7756E-17 -3.0416"/>
    <parent link="right_link51"/>
    <child link="right_link52"/>
    <axis xyz="0 0 1"/>
    <limit lower="-0.934" upper="0.055" effort="1" velocity="1"/>
  </joint>
  <link name="right_link53">
    <inertial>
      <origin xyz="0.0104629360450728 0.00192820283562468 -3.38351464429509E-06" rpy="0 0 0"/>
      <mass value="0.00330869122519449"/>
      <inertia ixx="8.21794532311926e-05" ixy="1.14153196955289e-05" ixz="-1.49218673904795e-07" iyy="0.000190093466236439" iyz="3.77060351806357e-08" izz="0.000196169077984371" />
    </inertial>
    <visual>
      <origin xyz="0 0 0" rpy="0 0 0"/>
      <geometry>
        <mesh filename="meshes/inspire_hand/thumb_tip.glb"/>
      </geometry>
    </visual>
    <collision>
      <origin xyz="0 0 0" rpy="0 0 0"/>
      <geometry>
        <mesh filename="meshes/inspire_hand/thumb_tip.glb"/>
      </geometry>
    </collision>
  </link>
  <joint name="right_joint53" type="revolute">
    <origin xyz="-0.022653 0 0" rpy="1.2712E-14 -9.7145E-17 2.856"/>
    <parent link="right_link52"/>
    <child link="right_link53"/>
    <axis xyz="0 0 1"/>
    <limit lower="-1.055" upper="0.138" effort="1" velocity="1"/>
  </joint>

</robot>
