<?xml version="1.0" ?>
<!-- =================================================================================== -->
<!-- |    This document was autogenerated by xacro from main.xacro                     | -->
<!-- |    EDITING THIS FILE BY HAND IS NOT RECOMMENDED                                 | -->
<!-- =================================================================================== -->
<robot name="inspire_hand">
  <link name="right_hand_wrist_base_link">
    <inertial>
      <origin rpy="0 0 0" xyz="2.5182E-06 0.0014729 0.032787"/>
      <mass value="0.065373"/>
      <inertia ixx="4.1551E-05" ixy="7.0443E-11" ixz="-6.0666E-09" iyy="4.1183E-05" iyz="8.3238E-09" izz="2.7992E-05"/>
    </inertial>
    <visual>
      <origin rpy="0 0 0" xyz="0 0 0"/>
      <geometry>
        <mesh filename="../../../meshes/end_effector/inspire_hand/visual/wrist_base_link.glb"/>
      </geometry>
    </visual>
    <collision>
      <origin rpy="0 0 0" xyz="0 0 0"/>
      <geometry>
        <mesh filename="../../../meshes/end_effector/inspire_hand/visual/wrist_base_link.glb"/>
      </geometry>
    </collision>
  </link>
  <link name="right_hand_wrist_link">
    <inertial>
      <origin rpy="0 0 0" xyz="4.5229E-10 -7.0516E-06 -7.9885E-05"/>
      <mass value="0.00056124"/>
      <inertia ixx="2.9483E-08" ixy="-1.2003E-15" ixz="6.7402E-16" iyy="2.9284E-08" iyz="3.1625E-13" izz="2.2194E-09"/>
    </inertial>
    <visual>
      <origin rpy="0 0 0" xyz="0 0 0"/>
      <geometry>
        <mesh filename="../../../meshes/end_effector/inspire_hand/visual/R_wrist_link.glb"/>
      </geometry>
    </visual>
    <collision>
      <origin rpy="0 0 0" xyz="0 0 0"/>
      <geometry>
        <mesh filename="../../../meshes/end_effector/inspire_hand/visual/R_wrist_link.glb"/>
      </geometry>
    </collision>
  </link>
  <joint name="right_hand_wrist_pitch_joint" type="revolute">
    <origin rpy="1.5707963267948966 0 1.5707963267948966" xyz="0 0 0.0785"/>
    <parent link="right_hand_wrist_base_link"/>
    <child link="right_hand_wrist_link"/>
    <axis xyz="0 0 1"/>
    <limit effort="1" lower="-0.39549160850191506" upper="0.3860668305411457" velocity="0.5"/>
  </joint>
  <link name="right_hand_hand_base_link">
    <inertial>
      <origin rpy="0 0 0" xyz="-0.001139 0.05204 -0.0013473"/>
      <mass value="0.19286"/>
      <inertia ixx="9.3622E-05" ixy="-1.7899E-06" ixz="6.7062E-07" iyy="9.545E-05" iyz="2.7767E-06" izz="0.00016048"/>
    </inertial>
    <visual>
      <origin rpy="0 0 0" xyz="0 0 0"/>
      <geometry>
        <mesh filename="../../../meshes/end_effector/inspire_hand/visual/R_hand_base_link.glb"/>
      </geometry>
    </visual>
    <collision>
      <origin rpy="0 0 0" xyz="0 0 0"/>
      <geometry>
        <mesh filename="../../../meshes/end_effector/inspire_hand/visual/R_hand_base_link.glb"/>
      </geometry>
    </collision>
  </link>
  <joint name="right_hand_wrist_yaw_joint" type="revolute">
    <origin rpy="0 1.5707963267948966 0" xyz="0 0 0"/>
    <parent link="right_hand_wrist_link"/>
    <child link="right_hand_hand_base_link"/>
    <axis xyz="0 0 1"/>
    <limit effort="1" lower="-0.445058959258554" upper="0.445058959258554" velocity="0.5"/>
  </joint>
  <link name="right_hand_thumb_metacarpal_base">
    <inertial>
      <origin rpy="0 0 0" xyz="0.003828 0.0005479 2.5426E-05"/>
      <mass value="0.0015178"/>
      <inertia ixx="3.6056E-08" ixy="5.7714E-09" ixz="1.9601E-09" iyy="6.0741E-08" iyz="-2.0748E-10" izz="5.6162E-08"/>
    </inertial>
    <visual>
      <origin rpy="0 0 0" xyz="0 0 0"/>
      <geometry>
        <mesh filename="../../../meshes/end_effector/inspire_hand/visual/R_thumb_metacarpal_base.glb"/>
      </geometry>
    </visual>
    <collision>
      <origin rpy="0 0 0" xyz="0 0 0"/>
      <geometry>
        <mesh filename="../../../meshes/end_effector/inspire_hand/visual/R_thumb_metacarpal_base.glb"/>
      </geometry>
    </collision>
  </link>
  <joint name="right_hand_thumb_CMC_yaw_joint" type="revolute">
    <origin rpy="-1.5707963267948966 -0.2617993877991494 0" xyz="0.02125 0.0285 0.01515"/>
    <parent link="right_hand_hand_base_link"/>
    <child link="right_hand_thumb_metacarpal_base"/>
    <axis xyz="0 0 1"/>
    <limit effort="1" lower="-1.3089969389957472" upper="0" velocity="0.5"/>
  </joint>
  <link name="right_hand_thumb_metacarpal">
    <inertial>
      <origin rpy="0 0 0" xyz="0.025599 0.0011669 7.3555E-08"/>
      <mass value="0.026112"/>
      <inertia ixx="2.4138E-06" ixy="1.4258E-07" ixz="-3.1577E-11" iyy="6.7222E-06" iyz="6.0585E-12" izz="7.9398E-06"/>
    </inertial>
    <visual>
      <origin rpy="0 0 0" xyz="0 0 0"/>
      <geometry>
        <mesh filename="../../../meshes/end_effector/inspire_hand/visual/thumb_metacarpal.glb"/>
      </geometry>
    </visual>
    <collision>
      <origin rpy="0 0 0" xyz="0 0 0"/>
      <geometry>
        <mesh filename="../../../meshes/end_effector/inspire_hand/visual/thumb_metacarpal.glb"/>
      </geometry>
    </collision>
  </link>
  <joint name="right_hand_thumb_CMC_pitch_joint" type="revolute">
    <origin rpy="-1.5707963267948966 -0.6831165238198015 0" xyz="0.0115 0 -0.00075"/>
    <parent link="right_hand_thumb_metacarpal_base"/>
    <child link="right_hand_thumb_metacarpal"/>
    <axis xyz="0 0 1"/>
    <limit effort="1" lower="-0.4799655442984406" upper="0" velocity="0.5"/>
  </joint>
  <link name="right_hand_thumb_proximal">
    <inertial>
      <origin rpy="0 0 0" xyz="0.0096374 0.0056519 -3.2431E-08"/>
      <mass value="0.0076245"/>
      <inertia ixx="3.7134E-07" ixy="9.4961E-08" ixz="6.3265E-12" iyy="7.908E-07" iyz="2.8577E-12" izz="8.6329E-07"/>
    </inertial>
    <visual>
      <origin rpy="0 0 0" xyz="0 0 0"/>
      <geometry>
        <mesh filename="../../../meshes/end_effector/inspire_hand/visual/thumb_proximal.glb"/>
      </geometry>
    </visual>
    <collision>
      <origin rpy="0 0 0" xyz="0 0 0"/>
      <geometry>
        <mesh filename="../../../meshes/end_effector/inspire_hand/visual/thumb_proximal.glb"/>
      </geometry>
    </collision>
  </link>
  <joint name="right_hand_thumb_MCP_joint" type="revolute">
    <origin rpy="0 0 -0.0031723" xyz="0.055852 -0.0040666 0"/>
    <parent link="right_hand_thumb_metacarpal"/>
    <child link="right_hand_thumb_proximal"/>
    <axis xyz="0 0 1"/>
    <limit effort="1" lower="-0.8" upper="0" velocity="0.5"/>
    <!-- <mimic joint="right_hand_thumb_CMC_pitch_joint" multiplier="1.3333333333333335" offset="-0.08144869842640205"/> -->
  </joint>
  <link name="right_hand_thumb_distal">
    <inertial>
      <origin rpy="0 0 0" xyz="0.01088 0.00050953 -7.3208E-08"/>
      <mass value="0.0032026"/>
      <inertia ixx="8.1419E-08" ixy="2.1824E-08" ixz="-2.8228E-13" iyy="1.751E-07" iyz="1.4206E-12" izz="1.8651E-07"/>
    </inertial>
    <visual>
      <origin rpy="0 0 0" xyz="0 0 0"/>
      <geometry>
        <mesh filename="../../../meshes/end_effector/inspire_hand/visual/thumb_distal.glb"/>
      </geometry>
    </visual>
    <collision>
      <origin rpy="0 0 0" xyz="0 0 0"/>
      <geometry>
        <mesh filename="../../../meshes/end_effector/inspire_hand/visual/thumb_distal.glb"/>
      </geometry>
    </collision>
  </link>
  <joint name="right_hand_thumb_IP_joint" type="revolute">
    <origin rpy="0 0 0.011853" xyz="0.022558 0.0020717 0"/>
    <parent link="right_hand_thumb_proximal"/>
    <child link="right_hand_thumb_distal"/>
    <axis xyz="0 0 1"/>
    <limit effort="1" lower="-0.4" upper="0" velocity="0.5"/>
    <!-- <mimic joint="right_hand_thumb_CMC_pitch_joint" multiplier="0.6666666666666667" offset="-0.040724349213201026"/> -->
  </joint>
  <link name="right_hand_index_proximal">
    <inertial>
      <origin rpy="0 0 0" xyz="0.013292 -0.0019852 6.3987E-08"/>
      <mass value="0.0074557"/>
      <inertia ixx="3.0933E-07" ixy="1.1169E-07" ixz="6.8599E-12" iyy="8.2022E-07" iyz="4.1194E-13" izz="9.125E-07"/>
    </inertial>
    <visual>
      <origin rpy="0 0 0" xyz="0 0 0"/>
      <geometry>
        <mesh filename="../../../meshes/end_effector/inspire_hand/visual/index_ring_proximal.glb"/>
      </geometry>
    </visual>
    <collision>
      <origin rpy="0 0 0" xyz="0 0 0"/>
      <geometry>
        <mesh filename="../../../meshes/end_effector/inspire_hand/visual/index_ring_proximal.glb"/>
      </geometry>
    </collision>
  </link>
  <joint name="right_hand_index_MCP_joint" type="revolute">
    <origin rpy="-1.5707963267948966 0.12457000000000001 1.5359" xyz="0.027071 0.10464 -0.0020953"/>
    <parent link="right_hand_hand_base_link"/>
    <child link="right_hand_index_proximal"/>
    <axis xyz="0 0 1"/>
    <limit effort="1" lower="-1.34" upper="0" velocity="0.5"/>
  </joint>
  <link name="right_hand_index_middle">
    <inertial>
      <origin rpy="0 0 0" xyz="0.018926 -0.0015379 -2.8949E-08"/>
      <mass value="0.0044472"/>
      <inertia ixx="1.4776E-07" ixy="2.0201E-07" ixz="5.0844E-13" iyy="6.6739E-07" iyz="-2.7579E-13" izz="7.4626E-07"/>
    </inertial>
    <visual>
      <origin rpy="0 0 0" xyz="0 0 0"/>
      <geometry>
        <mesh filename="../../../meshes/end_effector/inspire_hand/visual/index_ring_middle.glb"/>
      </geometry>
    </visual>
    <collision>
      <origin rpy="0 0 0" xyz="0 0 0"/>
      <geometry>
        <mesh filename="../../../meshes/end_effector/inspire_hand/visual/index_ring_middle.glb"/>
      </geometry>
    </collision>
  </link>
  <joint name="right_hand_index_PIP_joint" type="revolute">
    <origin rpy="0 0 0.0016248" xyz="0.030445 -0.010275 0"/>
    <parent link="right_hand_index_proximal"/>
    <child link="right_hand_index_middle"/>
    <axis xyz="0 0 1"/>
    <limit effort="1" lower="-1.56" upper="0.04545" velocity="0.5"/>
    <!-- <mimic joint="right_hand_index_MCP_joint" multiplier="1.06399" offset="-0.16734800000000002"/> -->
  </joint>
  <link name="right_hand_middle_proximal">
    <inertial>
      <origin rpy="0 0 0" xyz="0.013292 -0.0019853 9.6516E-08"/>
      <mass value="0.0074556"/>
      <inertia ixx="3.0932E-07" ixy="1.1169E-07" ixz="7.0517E-12" iyy="8.2022E-07" iyz="-8.1193E-13" izz="9.1249E-07"/>
    </inertial>
    <visual>
      <origin rpy="0 0 0" xyz="0 0 0"/>
      <geometry>
        <mesh filename="../../../meshes/end_effector/inspire_hand/visual/middle_pinky_proximal.glb"/>
      </geometry>
    </visual>
    <collision>
      <origin rpy="0 0 0" xyz="0 0 0"/>
      <geometry>
        <mesh filename="../../../meshes/end_effector/inspire_hand/visual/middle_pinky_proximal.glb"/>
      </geometry>
    </collision>
  </link>
  <joint name="right_hand_middle_MCP_joint" type="revolute">
    <origin rpy="-1.5707963267948966 0.12457000000000001 1.5707963267948966" xyz="0.00775 0.105 -0.0020953"/>
    <parent link="right_hand_hand_base_link"/>
    <child link="right_hand_middle_proximal"/>
    <axis xyz="0 0 1"/>
    <limit effort="1" lower="-1.34" upper="0" velocity="0.5"/>
  </joint>
  <link name="right_hand_middle_middle">
    <inertial>
      <origin rpy="0 0 0" xyz="0.020219 -0.0014517 -6.6609E-10"/>
      <mass value="0.0048916"/>
      <inertia ixx="1.6257E-07" ixy="2.4464E-07" ixz="5.557E-13" iyy="8.8194E-07" iyz="-1.7464E-13" izz="9.6869E-07"/>
    </inertial>
    <visual>
      <origin rpy="0 0 0" xyz="0 0 0"/>
      <geometry>
        <mesh filename="../../../meshes/end_effector/inspire_hand/visual/middle_middle.glb"/>
      </geometry>
    </visual>
    <collision>
      <origin rpy="0 0 0" xyz="0 0 0"/>
      <geometry>
        <mesh filename="../../../meshes/end_effector/inspire_hand/visual/middle_middle.glb"/>
      </geometry>
    </collision>
  </link>
  <joint name="right_hand_middle_PIP_joint" type="revolute">
    <origin rpy="0 0 -0.019795" xyz="0.030445 -0.010275 0"/>
    <parent link="right_hand_middle_proximal"/>
    <child link="right_hand_middle_middle"/>
    <axis xyz="0 0 1"/>
    <limit effort="1" lower="-1.56" upper="0.04545" velocity="0.5"/>
    <!-- <mimic joint="right_hand_middle_MCP_joint" multiplier="1.06399" offset="-0.16734800000000002"/> -->
  </joint>
  <link name="right_hand_ring_proximal">
    <inertial>
      <origin rpy="0 0 0" xyz="0.013292 -0.0019853 9.267E-08"/>
      <mass value="0.0074556"/>
      <inertia ixx="3.0932E-07" ixy="1.1169E-07" ixz="6.3806E-12" iyy="8.2022E-07" iyz="-3.6905E-13" izz="9.1249E-07"/>
    </inertial>
    <visual>
      <origin rpy="0 0 0" xyz="0 0 0"/>
      <geometry>
        <mesh filename="../../../meshes/end_effector/inspire_hand/visual/index_ring_proximal.glb"/>
      </geometry>
    </visual>
    <collision>
      <origin rpy="0 0 0" xyz="0 0 0"/>
      <geometry>
        <mesh filename="../../../meshes/end_effector/inspire_hand/visual/index_ring_proximal.glb"/>
      </geometry>
    </collision>
  </link>
  <joint name="right_hand_ring_MCP_joint" type="revolute">
    <origin rpy="-1.5707963267948966 0.12457000000000001 1.6232" xyz="-0.011479 0.1045 -0.0020953"/>
    <parent link="right_hand_hand_base_link"/>
    <child link="right_hand_ring_proximal"/>
    <axis xyz="0 0 1"/>
    <limit effort="1" lower="-1.34" upper="0" velocity="0.5"/>
  </joint>
  <link name="right_hand_ring_middle">
    <inertial>
      <origin rpy="0 0 0" xyz="0.018926 -0.0015379 -2.2489E-08"/>
      <mass value="0.0044472"/>
      <inertia ixx="1.4776E-07" ixy="2.0201E-07" ixz="-3.2151E-13" iyy="6.6738E-07" iyz="3.8885E-13" izz="7.4626E-07"/>
    </inertial>
    <visual>
      <origin rpy="0 0 0" xyz="0 0 0"/>
      <geometry>
        <mesh filename="../../../meshes/end_effector/inspire_hand/visual/index_ring_middle.glb"/>
      </geometry>
    </visual>
    <collision>
      <origin rpy="0 0 0" xyz="0 0 0"/>
      <geometry>
        <mesh filename="../../../meshes/end_effector/inspire_hand/visual/index_ring_middle.glb"/>
      </geometry>
    </collision>
  </link>
  <joint name="right_hand_ring_PIP_joint" type="revolute">
    <origin rpy="0 0 0.0016262" xyz="0.030445 -0.010275 0"/>
    <parent link="right_hand_ring_proximal"/>
    <child link="right_hand_ring_middle"/>
    <axis xyz="0 0 1"/>
    <limit effort="1" lower="-1.56" upper="0.04545" velocity="0.5"/>
    <!-- <mimic joint="right_hand_ring_MCP_joint" multiplier="1.06399" offset="-0.16734800000000002"/> -->
  </joint>
  <link name="right_hand_pinky_proximal">
    <inertial>
      <origin rpy="0 0 0" xyz="0.013292 -0.0019853 9.9172E-08"/>
      <mass value="0.0074556"/>
      <inertia ixx="3.0932E-07" ixy="1.1169E-07" ixz="6.5494E-12" iyy="8.2022E-07" iyz="-6.477E-13" izz="9.1249E-07"/>
    </inertial>
    <visual>
      <origin rpy="0 0 0" xyz="0 0 0"/>
      <geometry>
        <mesh filename="../../../meshes/end_effector/inspire_hand/visual/middle_pinky_proximal.glb"/>
      </geometry>
    </visual>
    <collision>
      <origin rpy="0 0 0" xyz="0 0 0"/>
      <geometry>
        <mesh filename="../../../meshes/end_effector/inspire_hand/visual/middle_pinky_proximal.glb"/>
      </geometry>
    </collision>
  </link>
  <joint name="right_hand_pinky_MCP_joint" type="revolute">
    <origin rpy="-1.5707963267948966 0.12457000000000001 1.6755" xyz="-0.030655 0.10299 -0.0020953"/>
    <parent link="right_hand_hand_base_link"/>
    <child link="right_hand_pinky_proximal"/>
    <axis xyz="0 0 1"/>
    <limit effort="1" lower="-1.34" upper="0" velocity="0.5"/>
  </joint>
  <link name="right_hand_pinky_middle">
    <inertial>
      <origin rpy="0 0 0" xyz="0.015705 -0.001732 -3.0224E-05"/>
      <mass value="0.00358"/>
      <inertia ixx="1.1688E-07" ixy="1.3011E-07" ixz="5.7801E-10" iyy="3.6707E-07" iyz="-3.7876E-10" izz="4.2838E-07"/>
    </inertial>
    <visual>
      <origin rpy="0 0 0" xyz="0 0 0"/>
      <geometry>
        <mesh filename="../../../meshes/end_effector/inspire_hand/visual/pinky_middle.glb"/>
      </geometry>
    </visual>
    <collision>
      <origin rpy="0 0 0" xyz="0 0 0"/>
      <geometry>
        <mesh filename="../../../meshes/end_effector/inspire_hand/visual/pinky_middle.glb"/>
      </geometry>
    </collision>
  </link>
  <joint name="right_hand_pinky_PIP_joint" type="revolute">
    <origin rpy="0 0 0.090322" xyz="0.030445 -0.010275 0"/>
    <parent link="right_hand_pinky_proximal"/>
    <child link="right_hand_pinky_middle"/>
    <axis xyz="0 0 1"/>
    <limit effort="1" lower="-1.56" upper="0.04545" velocity="0.5"/>
    <!-- <mimic joint="right_hand_pinky_MCP_joint" multiplier="1.06399" offset="-0.16734800000000002"/> -->
  </joint>
  <link name="right_hand_thumb_tip"/>
  <joint name="right_hand_thumb_tip_joint" type="fixed">
    <origin rpy="0 0 0" xyz="0.024859 -0.000031 0"/>
    <parent link="right_hand_thumb_distal"/>
    <child link="right_hand_thumb_tip"/>
  </joint>
  <link name="right_hand_index_tip"/>
  <joint name="right_hand_index_tip_joint" type="fixed">
    <origin rpy="0 0 0" xyz="0.043944 -0.009147 0"/>
    <parent link="right_hand_index_middle"/>
    <child link="right_hand_index_tip"/>
  </joint>
  <link name="right_hand_middle_tip"/>
  <joint name="right_hand_middle_tip_joint" type="fixed">
    <origin rpy="0 0 0" xyz="0.047746 -0.009066 0"/>
    <parent link="right_hand_middle_middle"/>
    <child link="right_hand_middle_tip"/>
  </joint>
  <link name="right_hand_ring_tip"/>
  <joint name="right_hand_ring_tip_joint" type="fixed">
    <origin rpy="0 0 0" xyz="0.043944 -0.009147 0"/>
    <parent link="right_hand_ring_middle"/>
    <child link="right_hand_ring_tip"/>
  </joint>
  <link name="right_hand_pinky_tip"/>
  <joint name="right_hand_pinky_tip_joint" type="fixed">
    <origin rpy="0 0 0" xyz="0.035855 -0.009619 0"/>
    <parent link="right_hand_pinky_middle"/>
    <child link="right_hand_pinky_tip"/>
  </joint>
  <!-- Left arm -->
</robot>
